Workbook

Sheet Sheet1
A1: CROP IDENTIFICATION | D1: NUTRITIONAL DATA (per 100 g) | AB1: ECOCROP DATABASE — ALL FIELDS | CI1: PLANT MORPHOLOGY (USDA PLANTS Database) | CN1: YIELD POTENTIAL (FAOSTAT / FAO / USDA) | CR1: FARM LABOUR — MECHANISED / COMMERCIAL SYSTEM (hours / ha) | DA1: FARM LABOUR — MANUAL / SMALLHOLDER SYSTEM (hours / ha) | DJ1: LABOUR DATA SOURCE | DK1: FOOD GROUP & SERVING SIZE (Australian Dietary Guidelines 2013) | DN1: HARVEST CALENDAR (Australian Growing Conditions — Southern Hemisphere) | EB1: STORAGE & PRESERVATION (USDA / NSW DPI / FAO / Hort Innovation)
A2: Crop Name | B2: Edible Part | C2: AFCD Food Entry Used | D2: Calories (kcal) | E2: Protein (g) | F2: Fat (g) | G2: Carbohydrate (g) | H2: Fiber (g) | I2: Ca (mg) | J2: Fe (mg) | K2: Mg (mg) | L2: P (mg) | M2: K (mg) | N2: Na (mg) | O2: Zn (mg) | P2: Cu (mg) | Q2: Mn (mg) | R2: Se (µg) | S2: VitA (µg RE) | T2: VitE (mg) | U2: VitC (mg) | V2: B1 (mg) | W2: B2 (mg) | X2: B3 (mg) | Y2: B6 (mg) | Z2: B12 (µg) | AA2: B9/Folate (µg) | AB2: EcoPortCode | AC2: ScientificName | AD2: AUTH | AE2: FAMNAME | AF2: SYNO | AG2: COM | AH2: COMNAME | AI2: SUIT | AJ2: LIFO | AK2: HABI | AL2: LISPA | AM2: SEASON | AN2: PHYS | AO2: CAT | AP2: CAT2 | AQ2: PLAT | AR2: TOPMN | AS2: TOPMX | AT2: TMIN | AU2: TMAX | AV2: ROPMN | AW2: ROPMX | AX2: RMIN | AY2: RMAX | AZ2: PHOPMN | BA2: PHOPMX | BB2: PHMIN | BC2: PHMAX | BD2: LATOPMN | BE2: LATOPMX | BF2: LATMN | BG2: LATMX | BH2: ALTMX | BI2: LIOPMN | BJ2: LIOPMX | BK2: LIMN | BL2: LIMX | BM2: DEP | BN2: DEPR | BO2: TEXT | BP2: TEXTR | BQ2: FER | BR2: FERR | BS2: TOX | BT2: TOXR | BU2: SAL | BV2: SALR | BW2: DRA | BX2: DRAR | BY2: KTMPR | BZ2: KTMP | CA2: PHOTO | CB2: CLIZ | CC2: ABITOL | CD2: ABISUS | CE2: INTRI | CF2: PROSY | CG2: GMIN | CH2: GMAX | CI2: Height Min (m) | CJ2: Height Max (m) | CK2: Width/Spread Min (m) | CL2: Width/Spread Max (m) | CM2: Morphology Notes | CN2: Yield Low (t/ha) | CO2: Yield High (t/ha) | CP2: Yield Notes | CQ2: Yield Source | CR2: Mech Land Prep (h/ha) | CS2: Mech Sow/Plant (h/ha) | CT2: Mech Weed (h/ha) | CU2: Mech Fertilise (h/ha) | CV2: Mech Pest/Disease (h/ha) | CW2: Mech Prune/Train (h/ha) | CX2: Mech Irrigate (h/ha) | CY2: Mech Harvest (h/ha) | CZ2: Mech Post-Harvest (h/ha) | DA2: Hand Land Prep (h/ha) | DB2: Hand Sow/Plant (h/ha) | DC2: Hand Weed (h/ha) | DD2: Hand Fertilise (h/ha) | DE2: Hand Pest/Disease (h/ha) | DF2: Hand Prune/Train (h/ha) | DG2: Hand Irrigate (h/ha) | DH2: Hand Harvest (h/ha) | DI2: Hand Post-Harvest (h/ha) | DJ2: Labour Data Source | DK2: ADG Food Group | DL2: ADG Serve Size (g) | DM2: ADG Serve Notes | DN2: Jan | DO2: Feb | DP2: Mar | DQ2: Apr | DR2: May | DS2: Jun | DT2: Jul | DU2: Aug | DV2: Sep | DW2: Oct | DX2: Nov | DY2: Dec | DZ2: Australian Region / Season Notes | P = Peak harvest S = Shoulder season | EA2: Northern Hemisphere Equivalent | EB2: Storability Class | EC2: Primary Storage Method | ED2: Storage Duration (months) | EE2: Processing Labour (h/100kg) | EF2: Cool Storage Only (no processing)
A3: Brazil Nut | B3: Nut | C3: Nut, brazil, raw or blanched, unsalted | D3: 689.8 | E3: 14.4 | F3: 68.5 | G3: 2.4 | H3: 8.5 | I3: 150 | J3: 2.2 | K3: 350 | L3: 660 | M3: 560 | N3: 2 | O3: 4.1 | P3: 2 | Q3: 0.84 | R3: 1917 | S3: 2 | T3: 5.3 | U3: 0 | V3: 0.6 | W3: 0.43 | X3: 0.6 | Y3: 0.27 | Z3: 0 | AA3: 22 | AB3: 3699 | AC3: Bertholletia excelsa | AD3: Humb. & Bonpl. | AE3: Magnoliopsida:Dilleniidae:Lecythidales:Lecythidaceae | AF3: Bertholletia nobilis Miers, Bertholletia myrtaceae | AG3: Brazil nut | AH3: Brazil nut, para nut, noyer du Brésil, la noix du Brésil, el coquito del Brasil, castanha do Para, castanha do Brasil, castanheiro do para, die paranüsse, la noce del Brasile | AI3: poorly suited | AJ3: tree | AK3: erect | AL3: perennial | AN3: semi evergreen, deciduous, single stem | AO3: fruits & nuts, forest/wood | AP3: nuts | AQ3: grown on small scale | AR3: 20 | AS3: 36 | AT3: 12 | AU3: 40 | AV3: 2400 | AW3: 2800 | AX3: 1400 | AY3: 3500 | AZ3: 5.5 | BA3: 7 | BB3: 4.5 | BC3: 8 | BF3: 10 | BG3: 10 | BH3: 200 | BI3: clear skies | BJ3: cloudy skies | BK3: clear skies | BL3: light shade | BM3: deep (>>150 cm) | BN3: medium (50-150 cm) | BO3: heavy, medium | BP3: heavy, medium | BQ3: high | BR3: moderate | BU3: low (<4 dS/m) | BV3: low (<4 dS/m) | BW3: well (dry spells) | BX3: well (dry spells) | CA3: short day (<12 hours), neutral day (12-14 hours), long day (>14 hours) | CB3: tropical wet & dry (Aw), tropical wet (Ar) | CF3: small scale (manual) | CG3: 365 | CH3: 365 | CI3: 30 | CJ3: 50 | CK3: 15 | CL3: 30 | CM3: Very large rainforest tree | CN3: 0.1 | CO3: 0.5 | CP3: Wild harvest from forest; very low intensity | CQ3: FAO; FAOSTAT | CR3: 0 | CS3: 0 | CT3: 3 | CU3: 2 | CV3: 2 | CW3: 0 | CX3: 0 | CY3: 20 | CZ3: 15 | DA3: 0 | DB3: 0 | DC3: 20 | DD3: 10 | DE3: 10 | DF3: 0 | DG3: 0 | DH3: 400 | DI3: 250 | DJ3: LIT Amazon — almost entirely wild harvest; pod collection | DK3: Lean Meats, Eggs, Nuts, Seeds & Legumes | DL3: 30 | DM3: 30g Brazil nuts (~3 nuts); occasional substitute | DN3: P | DO3: P | DP3: S | DX3: S | DY3: P | DZ3: Very limited FNQ tropical — pods fall Nov–Mar | EA3: NH: Jan–Mar (Amazon Basin — wild harvest) | EB3: Medium Storage | EC3: In-shell: cool/dry; shelled: refrigerate | ED3: 3–12 months | EE3: 2 | EF3: 1–6 months
A4: Chickpea | B4: Seed | C4: Chickpea, dried | D4: 328.2 | E4: 19.7 | F4: 5.5 | G4: 38.5 | H4: 20.8 | I4: 159 | J4: 4.6 | K4: 134 | L4: 296 | M4: 396 | N4: 11 | O4: 3.1 | P4: 0.877 | Q4: 2.151 | R4: 68 | S4: 11 | T4: 1.73 | U4: 3 | V4: 0.57 | W4: 0.02 | X4: 1.3 | Y4: 2.6 | Z4: 0 | AA4: 178 | AB4: 2479 | AC4: Cicer arietinum | AD4: L. | AE4: Magnoliopsida:Rosidae:Fabales:Leguminosae | AG4: chickpea | AH4: chickpea, Bengal gram, pois chiche, cafe francais, gravancos, sigro, hanaz, djelbane | AI4: suitable | AJ4: herb | AK4: erect | AL4: annual | AM4: COOL | AO4: pulses (grain legumes) | AP4: pulses (grain legumes) | AQ4: grown on large scale, grown on small scale | AR4: 15 | AS4: 29 | AT4: 7 | AU4: 35 | AV4: 600 | AW4: 1000 | AX4: 300 | AY4: 1800 | AZ4: 6 | BA4: 8.5 | BB4: 4.7 | BC4: 9.5 | BF4: 30 | BG4: 50 | BH4: 2300 | BI4: very bright | BJ4: very bright | BK4: very bright | BL4: clear skies | BM4: medium (50-150 cm) | BN4: shallow (20-50 cm) | BO4: heavy, medium | BP4: heavy, medium, light | BQ4: moderate | BR4: low | BU4: low (<4 dS/m) | BV4: medium (4-10 dS/m) | BW4: well (dry spells) | BX4: well (dry spells), excessive (dry/moderately dry) | BY4: -9 | BZ4: 0 | CA4: short day (<12 hours), neutral day (12-14 hours) | CB4: tropical wet & dry (Aw), tropical wet (Ar), desert or arid (Bw), steppe or semiarid (Bs), subtropical humid (Cf), subtropical dry summer (Cs), subtropical dry winter (Cw), temperate oceanic (Do), temperate continental (Dc), temperate with humid winters (Df), temperate with dry winters (Dw) | CG4: 90 | CH4: 180 | CI4: 0.2 | CJ4: 0.8 | CK4: 0.2 | CL4: 0.5 | CM4: Annual herb | CN4: 0.5 | CO4: 4 | CP4: Dry seed; Low: dryland; High: irrigated India/Australia | CQ4: FAOSTAT QCL | CR4: 3 | CS4: 2 | CT4: 4 | CU4: 1 | CV4: 2 | CW4: 0 | CX4: 2 | CY4: 4 | CZ4: 3 | DA4: 120 | DB4: 50 | DC4: 150 | DD4: 15 | DE4: 20 | DF4: 0 | DG4: 20 | DH4: 250 | DI4: 60 | DJ4: EXT Australia NSWDPI; FAO; LIT (Gezira) | DK4: Lean Meats, Eggs, Nuts, Seeds & Legumes | DL4: 150 | DM4: 1 cup cooked chickpeas (150g) | DV4: S | DW4: P | DX4: P | DY4: S | DZ4: QLD (winter dryland crop) — planted May, harvested Sep–Nov | EA4: NH: May–Jul (India, Pakistan) | EB4: Long Storage | EC4: Dry seed — cool/dry/dark, airtight | ED4: 12–36 months | EE4: 1 | EF4: 1–3 years
A5: Hemp Seed | B5: Seed | C5: Seed, hemp, dried | D5: 586 | E5: 29.8 | F5: 50.6 | G5: 2.5 | H5: 4.2 | I5: 90 | J5: 12.5 | K5: 650 | L5: 1520 | M5: 1060 | N5: 0 | O5: 9.4 | P5: 1.51 | Q5: 8.2 | R5: 36 | S5: 2 | T5: 1.26 | U5: 0 | V5: 1.6 | W5: 0.23 | X5: 3.6 | Y5: 0.57 | Z5: 0 | AA5: 150 | CI5: 1 | CJ5: 5 | CK5: 0.3 | CL5: 0.8 | CM5: Annual herb; fiber/seed type | CN5: 0.5 | CO5: 2 | CP5: Seed yield only; fiber types much lower seed yield | CQ5: FAOSTAT QCL; Est. | CR5: 3 | CS5: 1 | CT5: 3 | CU5: 1 | CV5: 1 | CW5: 0 | CX5: 1 | CY5: 4 | CZ5: 5 | DA5: 110 | DB5: 45 | DC5: 100 | DD5: 15 | DE5: 10 | DF5: 0 | DG5: 10 | DH5: 180 | DI5: 100 | DJ5: EXT; LIT | DK5: Lean Meats, Eggs, Nuts, Seeds & Legumes | DL5: 30 | DM5: 30g hemp seeds (~3 tbsp); occasional substitute | DO5: S | DP5: P | DQ5: P | DR5: S | DZ5: QLD, NSW, VIC (emerging) — warm-season; Feb–Apr harvest | EA5: NH: Aug–Sep (Canada, Europe) | EB5: Medium Storage | EC5: Cool/dark, airtight — refrigerate hulled | ED5: 3–12 months | EE5: 1 | EF5: 0.2–1 years
A6: Cashew | B6: Nut | C6: Nut, cashew, raw, unsalted | D6: 607.1 | E6: 17 | F6: 49.2 | G6: 22.9 | H6: 5.9 | I6: 34 | J6: 5 | K6: 250 | L6: 530 | M6: 550 | N6: 11 | O6: 5.5 | P6: 1.9 | Q6: 1.4 | R6: 33 | S6: 1 | T6: 0.73 | U6: 0 | V6: 0.64 | W6: 0.19 | X6: 1.8 | Y6: 0.35 | Z6: 0 | AA6: 25 | AB6: 401 | AC6: Anacardium occidentale | AD6: L. | AE6: Magnoliopsida:Rosidae:Sapindales:Anacardiaceae | AG6: mamuang himmaphan | AH6: mamuang himmaphan, yaruang, mamuang letlor, cashew, cashew nut, acajou á pomme, noix d'acajou, marañon, casho, cashu, cajou, anacardier, caju, acajú, kasjoe, mereke, kaju, apu initia, kesiu, cashewnuss, cashewbaum, jambu mortyet, jambu mede, gajus, jambu monyet, kasoy, balubad, balogo, thiho thayet si, svaay chantii, dao lon hot, cay dieu, nut-cashew | AI6: suitable | AJ6: shrub, tree | AK6: erect | AL6: perennial | AN6: evergreen, single stem, multi stem, C3 photosynthesis | AO6: fruits & nuts, medicinals & aromatic | AP6: nuts | AQ6: grown on large scale | AR6: 15 | AS6: 35 | AT6: 5 | AU6: 46 | AV6: 750 | AW6: 1600 | AX6: 400 | AY6: 4000 | AZ6: 4.5 | BA6: 6.5 | BB6: 3.8 | BC6: 8.7 | BF6: 25 | BG6: 30 | BH6: 1200 | BI6: very bright | BJ6: very bright | BK6: very bright | BL6: clear skies | BM6: deep (>>150 cm) | BN6: medium (50-150 cm) | BO6: medium, light | BP6: heavy, medium, light | BQ6: moderate | BR6: low | BU6: low (<4 dS/m) | BV6: low (<4 dS/m) | BW6: well (dry spells) | BX6: well (dry spells), excessive (dry/moderately dry) | CA6: short day (<12 hours), neutral day (12-14 hours), long day (>14 hours) | CB6: tropical wet & dry (Aw), steppe or semiarid (Bs), subtropical dry summer (Cs), subtropical dry winter (Cw) | CG6: 190 | CH6: 260 | CI6: 5 | CJ6: 12 | CK6: 5 | CL6: 10 | CM6: Tree | CN6: 0.3 | CO6: 2.5 | CP6: Nut in shell; Low: Africa/India; High: Vietnam intensive | CQ6: FAOSTAT QCL | CR6: 0 | CS6: 0 | CT6: 6 | CU6: 4 | CV6: 5 | CW6: 5 | CX6: 3 | CY6: 20 | CZ6: 15 | DA6: 0 | DB6: 0 | DC6: 50 | DD6: 25 | DE6: 35 | DF6: 40 | DG6: 20 | DH6: 400 | DI6: 300 | DJ6: FAO India/Vietnam; LIT — shelling very labour intensive | DK6: Lean Meats, Eggs, Nuts, Seeds & Legumes | DL6: 30 | DM6: 30g cashews (~18 cashews); occasional substitute | DV6: S | DW6: P | DX6: P | DY6: S | DZ6: FNQ tropical — limited production; spring–early summer | EA6: NH: Mar–Jun (India, Vietnam, Ivory Coast) | EB6: Long Storage | EC6: Dry, airtight — cool/dark | ED6: 6–12 months | EE6: 8 | EF6: 3–6 months
A7: Wattle Seed (Native) | B7: Seed | C7: Wattle seed (acacia), ground | D7: 282.7 | E7: 20.3 | F7: 6.1 | G7: 10.5 | H7: 54.2 | I7: 419 | J7: 6 | K7: 243 | L7: 70 | M7: 974 | N7: 102 | O7: 0.4 | P7: 0 | Q7: 1.7 | R7: 31.7 | S7: 0 | T7: 4.65 | U7: 0 | V7: 0.04 | W7: 0 | X7: 14.5 | Y7: 0.9 | Z7: 0 | AA7: 40 | CI7: 3 | CJ7: 8 | CK7: 2 | CL7: 6 | CM7: Shrub/small tree; Acacia | CN7: 0.1 | CO7: 0.5 | CP7: Wild harvest; emerging small-scale production; Australia | CQ7: Aust. Govt | CR7: 0 | CS7: 0 | CT7: 3 | CU7: 2 | CV7: 2 | CW7: 3 | CX7: 2 | CY7: 10 | CZ7: 10 | DA7: 0 | DB7: 0 | DC7: 20 | DD7: 10 | DE7: 10 | DF7: 20 | DG7: 15 | DH7: 200 | DI7: 150 | DJ7: Aust. Govt bush food; LIT — emerging; mainly wild | DK7: Lean Meats, Eggs, Nuts, Seeds & Legumes | DL7: 30 | DM7: 30g wattle seed powder; used as a flour/seed | DN7: S | DV7: S | DW7: P | DX7: P | DY7: P | DZ7: Arid SA/WA — harvested when pods dry and split; spring–summer | EA7: Australian endemic | EB7: Long Storage | EC7: Dry seed — cool/dark, airtight | ED7: 12–36 months | EE7: 3 | EF7: 1–3 years
A8: Amaranth (Grain) | B8: Grain | C8: Amaranth, grain, whole, uncooked | D8: 365 | E8: 15.2 | F8: 6.4 | G8: 55.6 | H8: 11.1 | I8: 147 | J8: 7 | K8: 237 | L8: 405 | M8: 508 | N8: 2 | O8: 2.7 | R8: 28 | S8: 0 | T8: 1 | U8: 4 | V8: 0.09 | W8: 0.04 | X8: 0 | Y8: 0.5 | Z8: 0 | AA8: 82 | AB8: 2187 | AC8: Amaranthus caudatus | AD8: L. | AE8: Magnoliopsida:Caryophyllidae:Caryophyllales:Amaranthaceae | AF8: Amaranthus cruentus L., Amaranthus dubius Thell., Amaranthus tricolor L., Amaranthus lividus L., Amaranthus viridus L., Amaranthus sanguineus L. | AG8: amaranths | AH8: amaranths, xian, lishalisho, ferenjitef, iyaso (Galinya), jolili (Galinya), gagabsa (Wollamo) | AI8: suitable | AJ8: herb | AK8: erect | AL8: annual | AM8: WARM | AN8: C4 photosynthesis | AO8: cereals & pseudocereals, forage/pasture, vegetables, ornamentals/turf, medicinals & aromatic | AP8: cereals & pseudocereals | AQ8: grown on small scale | AR8: 21 | AS8: 28 | AT8: 7 | AU8: 40 | AV8: 800 | AW8: 2300 | AX8: 250 | AY8: 4200 | AZ8: 5.5 | BA8: 7.5 | BB8: 4.3 | BC8: 8.5 | BF8: 40 | BG8: 40 | BH8: 3600 | BI8: very bright | BJ8: very bright | BK8: very bright | BL8: cloudy skies | BM8: medium (50-150 cm) | BN8: shallow (20-50 cm) | BO8: light, organic | BP8: heavy, medium, light | BQ8: moderate | BR8: low | BS8: none (<5% of CEC) | BT8: low (6-15% of CEC) | BU8: low (<4 dS/m) | BV8: medium (4-10 dS/m) | BW8: well (dry spells) | BX8: well (dry spells), excessive (dry/moderately dry) | BY8: 4 | BZ8: 0 | CA8: short day (<12 hours), neutral day (12-14 hours), long day (>14 hours) | CB8: tropical wet & dry (Aw), desert or arid (Bw), steppe or semiarid (Bs), subtropical humid (Cf), subtropical dry summer (Cs), subtropical dry winter (Cw) | CG8: 30 | CH8: 300 | CI8: 1 | CJ8: 3 | CK8: 0.3 | CL8: 0.6 | CM8: Annual grain; grain amaranth | CN8: 0.5 | CO8: 3 | CP8: Grain yield; Andean to commercial US | CQ8: FAO; USDA | CR8: 3 | CS8: 2 | CT8: 5 | CU8: 2 | CV8: 1 | CW8: 0 | CX8: 2 | CY8: 5 | CZ8: 5 | DA8: 110 | DB8: 60 | DC8: 200 | DD8: 20 | DE8: 10 | DF8: 0 | DG8: 20 | DH8: 250 | DI8: 100 | DJ8: EXT US; LIT | DK8: Grain (Cereal) Foods | DL8: 100 | DM8: ½ cup cooked amaranth (~100g) | DO8: S | DP8: P | DQ8: P | DR8: S | DZ8: Warm-season grain; QLD/NSW — autumn harvest | EA8: NH: Sep–Oct (Mexico, Peru) | EB8: Long Storage | EC8: Dry grain — cool/dry/dark, airtight | ED8: 12–24 months | EE8: 1 | EF8: 1–2 years
A9: Triticale | B9: Grain | C9: Triticale, grain, uncooked | D9: 325.3 | E9: 9.6 | F9: 2.4 | G9: 58.3 | H9: 14.4 | I9: 27 | J9: 3.55 | K9: 114 | L9: 245 | M9: 332 | N9: 5 | O9: 2.05 | R9: 26 | S9: 0 | T9: 1.15 | U9: 0 | V9: 0.355 | W9: 0.03 | X9: 1.7 | Y9: 0.2 | Z9: 0 | AA9: 73 | CI9: 0.8 | CJ9: 1.8 | CK9: 0.1 | CL9: 0.2 | CM9: Annual grass; wheat-rye hybrid | CN9: 2 | CO9: 8 | CP9: Hybrid wheat-rye; EU commercial | CQ9: FAOSTAT QCL | CR9: 3 | CS9: 1 | CT9: 1 | CU9: 1 | CV9: 1 | CW9: 0 | CX9: 0 | CY9: 2 | CZ9: 1 | DA9: 120 | DB9: 40 | DC9: 70 | DD9: 15 | DE9: 10 | DF9: 0 | DG9: 0 | DH9: 200 | DI9: 30 | DJ9: EXT; LIT | DK9: Grain (Cereal) Foods | DL9: 100 | DM9: ½ cup cooked triticale (~100g) | DN9: S | DW9: S | DX9: P | DY9: P | DZ9: SA, WA, VIC — spring harvest similar to wheat | EA9: NH: Jul–Aug (Europe) | EB9: Long Storage | EC9: Dry grain — cool/dry/dark, airtight | ED9: 12–36 months | EE9: 1 | EF9: 1–3 years
A10: Sesame Seed | B10: Seed | C10: Seed, sesame, unsalted | D10: 626.2 | E10: 22.2 | F10: 55.6 | G10: 6.2 | H10: 10.1 | I10: 62 | J10: 5.2 | K10: 340 | L10: 730 | M10: 170 | N10: 24 | O10: 5.5 | P10: 1.7 | Q10: 1.1 | R10: 22 | S10: 1 | T10: 1.68 | U10: 0 | V10: 0.99 | W10: 0.18 | X10: 5.1 | Y10: 0.25 | Z10: 0 | AA10: 115 | CI10: 0.5 | CJ10: 1.5 | CK10: 0.2 | CL10: 0.4 | CM10: Annual herb | CN10: 0.2 | CO10: 1.5 | CP10: Low: subsistence Africa; High: intensive India/Myanmar | CQ10: FAOSTAT QCL | CR10: 4 | CS10: 3 | CT10: 8 | CU10: 2 | CV10: 2 | CW10: 0 | CX10: 2 | CY10: 10 | CZ10: 8 | DA10: 130 | DB10: 70 | DC10: 280 | DD10: 20 | DE10: 20 | DF10: 0 | DG10: 20 | DH10: 350 | DI10: 150 | DJ10: FAO Asia/Africa; LIT — capsule shattering makes hand harvest tricky | DK10: Lean Meats, Eggs, Nuts, Seeds & Legumes | DL10: 30 | DM10: 30g sesame seeds or 2 tbsp tahini; occasional substitute | DP10: S | DQ10: P | DR10: P | DS10: S | DZ10: Tropical QLD/NT — warm-season; planted wet season, harvested dry season | EA10: NH: Oct–Nov (India, Myanmar, Sudan) | EB10: Long Storage | EC10: Dry seed — cool/dark, airtight | ED10: 12–36 months | EE10: 2 | EF10: 1–3 years
A11: Linseed / Flaxseed | B11: Seed | C11: Seed, linseed or flaxseed | D11: 450 | E11: 21.6 | F11: 32.6 | G11: 2.8 | H11: 32.9 | I11: 180 | J11: 5.5 | K11: 330 | L11: 490 | M11: 630 | N11: 60 | O11: 3.5 | P11: 0.86 | Q11: 3.1 | R11: 22 | S11: 0 | T11: 1.48 | U11: 0 | V11: 0.34 | W11: 0.03 | X11: 1.8 | Y11: 0.06 | Z11: 0 | AA11: 41 | CI11: 0.3 | CJ11: 1.2 | CK11: 0.1 | CL11: 0.3 | CM11: Annual herb | CN11: 0.5 | CO11: 2.5 | CP11: Seed yield; Canada/Russia dominant producers | CQ11: FAOSTAT QCL | CR11: 3 | CS11: 1 | CT11: 2 | CU11: 1 | CV11: 1 | CW11: 0 | CX11: 1 | CY11: 3 | CZ11: 2 | DA11: 110 | DB11: 40 | DC11: 80 | DD11: 15 | DE11: 10 | DF11: 0 | DG11: 10 | DH11: 180 | DI11: 40 | DJ11: EXT Canada; AHDB | DK11: Lean Meats, Eggs, Nuts, Seeds & Legumes | DL11: 30 | DM11: 30g linseeds (~2 tbsp); occasional substitute | DN11: S | DW11: S | DX11: P | DY11: P | DZ11: SA, VIC, WA — winter crop; harvested Oct–Dec | EA11: NH: Jul–Aug (Canada, Russia) | EB11: Long Storage | EC11: Dry seed — cool/dark, airtight; refrigerate ground | ED11: 12–24 months | EE11: 1 | EF11: 1–2 years
A12: Mushroom | B12: Fruiting Body | C12: Mushroom, common, fresh, raw | D12: 27.2 | E12: 2.2 | F12: 0.8 | G12: 0.8 | H12: 1.4 | I12: 2 | J12: 0.34 | K12: 10 | L12: 102 | M12: 385 | N12: 7 | O12: 0.3 | P12: 0.325 | Q12: 0.064 | R12: 17.5 | S12: 0 | T12: 0 | U12: 0 | V12: 0.06 | W12: 0 | X12: 3.55 | Y12: 0.01 | Z12: 0 | AA12: 30 | CI12: 0.05 | CJ12: 0.15 | CK12: 0.05 | CL12: 0.2 | CM12: Fruiting body size | CN12: 10 | CO12: 30 | CP12: Per m² basis converted; substrate yield ~25 kg/100 kg substrate | CQ12: FAO; USDA | CR12: 5 | CS12: 10 | CT12: 0 | CU12: 5 | CV12: 5 | CW12: 0 | CX12: 5 | CY12: 30 | CZ12: 15 | DA12: 50 | DB12: 100 | DC12: 0 | DD12: 50 | DE12: 40 | DF12: 0 | DG12: 40 | DH12: 400 | DI12: 200 | DJ12: ERS; EXT Pennsylvania; LIT — substrate prep, spawning, picking | DK12: Vegetables & Legumes | DL12: 75 | DM12: ½ cup cooked mushrooms | DN12: P | DO12: P | DP12: P | DQ12: P | DR12: P | DS12: P | DT12: P | DU12: P | DV12: P | DW12: P | DX12: P | DY12: P | DZ12: Year-round: grown in climate-controlled sheds; Australia-wide | EA12: Year-round globally (indoor cultivation) | EB12: Short Storage | EC12: Refrigerate; dry or pickle | ED12: 0 wks – 12 mo | EE12: 4 | EF12: 5–10 days
A13: Barley (Pearl) | B13: Grain | C13: Barley, pearl, uncooked | D13: 340.3 | E13: 9.9 | F13: 3.1 | G13: 60.6 | H13: 13.1 | I13: 28 | J13: 2.2 | K13: 95 | L13: 192 | M13: 350 | N13: 10 | O13: 1.2 | P13: 0.4 | Q13: 1.1 | R13: 17 | S13: 0 | T13: 0.7 | U13: 0 | V13: 0.17 | W13: 0.02 | X13: 6.6 | Y13: 0.2 | Z13: 0 | AA13: 23 | AB13: 1232 | AC13: Hordeum vulgare | AD13: L. | AE13: Liliopsida:Commelinidae:Cyperales:Gramineae | AF13: See Notes | AG13: barley | AH13: barley, cebada, orge, damai, cevada, gebs, Gerste | AI13: suitable | AJ13: grass | AK13: erect | AL13: annual | AM13: COOL | AO13: cereals & pseudocereals, medicinals & aromatic | AP13: cereals & pseudocereals | AQ13: grown on large scale | AR13: 15 | AS13: 20 | AT13: 2 | AU13: 40 | AV13: 500 | AW13: 1000 | AX13: 200 | AY13: 2000 | AZ13: 6.5 | BA13: 7.5 | BB13: 6 | BC13: 8 | BD13: 30 | BF13: 55 | BG13: 70 | BH13: 4400 | BI13: very bright | BJ13: very bright | BK13: very bright | BL13: cloudy skies | BM13: deep (>>150 cm) | BN13: medium (50-150 cm) | BO13: medium | BP13: heavy, medium, light | BQ13: moderate | BR13: low | BU13: low (<4 dS/m) | BV13: high (>10 dS/m)) | BW13: well (dry spells) | BX13: well (dry spells) | BY13: -4 | BZ13: 0 | CA13: neutral day (12-14 hours), long day (>14 hours) | CB13: tropical wet & dry (Aw), tropical wet (Ar), desert or arid (Bw), steppe or semiarid (Bs), subtropical humid (Cf), subtropical dry summer (Cs), subtropical dry winter (Cw), temperate oceanic (Do), temperate continental (Dc), temperate with humid winters (Df), temperate with dry winters (Dw) | CC13: drought | CD13: fire | CF13: large scale/commercial | CG13: 90 | CH13: 240 | CI13: 0.6 | CJ13: 1.2 | CK13: 0.1 | CL13: 0.2 | CM13: Annual grass; grain | CN13: 1.5 | CO13: 8 | CP13: Low: dryland; High: EU irrigated commercial; UK avg ~5 t/ha | CQ13: FAOSTAT QCL; HDC | CR13: 3 | CS13: 1 | CT13: 1 | CU13: 1 | CV13: 1 | CW13: 0 | CX13: 0 | CY13: 2 | CZ13: 1 | DA13: 120 | DB13: 40 | DC13: 80 | DD13: 15 | DE13: 10 | DF13: 0 | DG13: 0 | DH13: 200 | DI13: 30 | DJ13: AHDB cereals guide; ERS; LIT | DK13: Grain (Cereal) Foods | DL13: 100 | DM13: ½ cup cooked pearl barley (~100g) | DN13: S | DW13: S | DX13: P | DY13: P | DZ13: SA, WA, VIC — winter barley harvested Oct–Dec | EA13: NH: Jun–Aug | EB13: Long Storage | EC13: Dry grain — cool/dry/dark, airtight | ED13: 12–36 months | EE13: 1 | EF13: 1–3 years
A14: Lentil (Green) | B14: Seed | C14: Lentil, green, hulled, dry | D14: 317.9 | E14: 25.3 | F14: 1.7 | G14: 40.9 | H14: 14.6 | I14: 56 | J14: 5.6 | K14: 95 | L14: 286 | M14: 670 | N14: 13 | O14: 1.6 | R14: 16 | S14: 4 | T14: 0.7 | U14: 4 | V14: 0.22 | W14: 0.01 | X14: 1.6 | Y14: 0.4 | Z14: 0 | AA14: 80 | AB14: 7209 | AC14: Lens culinaris | AD14: Medikus | AE14: Magnoliopsida:Rosidae:Fabales:Leguminosae | AF14: Ervum lens L., Lens esculenta | AG14: lentil | AH14: lentil, red dhal, split pea, lentille, lenteja, lenticchia, adas, mercimek, messer, masser, heramame, shimfa, missr, linse | AI14: suitable | AJ14: herb | AK14: erect | AL14: annual | AM14: COOL | AN14: multi stem, C3 photosynthesis | AO14: pulses (grain legumes), medicinals & aromatic | AP14: pulses (grain legumes) | AQ14: grown on large scale | AR14: 15 | AS14: 29 | AT14: 5 | AU14: 32 | AV14: 600 | AW14: 1000 | AX14: 250 | AY14: 2500 | AZ14: 5.5 | BA14: 7.5 | BB14: 4.5 | BC14: 8.2 | BD14: 30 | BE14: 10 | BF14: 45 | BG14: 55 | BH14: 3800 | BI14: very bright | BJ14: very bright | BK14: very bright | BL14: cloudy skies | BM14: medium (50-150 cm) | BN14: shallow (20-50 cm) | BO14: heavy, medium | BP14: heavy, medium, light | BQ14: moderate | BR14: low | BU14: low (<4 dS/m) | BV14: medium (4-10 dS/m) | BW14: well (dry spells) | BX14: well (dry spells), excessive (dry/moderately dry) | CA14: neutral day (12-14 hours), long day (>14 hours) | CB14: tropical wet & dry (Aw), tropical wet (Ar), desert or arid (Bw), steppe or semiarid (Bs), subtropical humid (Cf), subtropical dry summer (Cs), subtropical dry winter (Cw), temperate oceanic (Do), temperate continental (Dc), temperate with humid winters (Df), temperate with dry winters (Dw) | CG14: 70 | CH14: 240 | CI14: 0.2 | CJ14: 0.8 | CK14: 0.2 | CL14: 0.4 | CM14: Annual herb | CN14: 0.5 | CO14: 3.5 | CP14: Dry seed; Low: dryland Canada/Turkey; High: irrigated | CQ14: FAOSTAT QCL | CR14: 3 | CS14: 2 | CT14: 4 | CU14: 1 | CV14: 2 | CW14: 0 | CX14: 1 | CY14: 4 | CZ14: 3 | DA14: 110 | DB14: 50 | DC14: 150 | DD14: 10 | DE14: 15 | DF14: 0 | DG14: 10 | DH14: 250 | DI14: 60 | DJ14: EXT Canada; NSWDPI; LIT | DK14: Lean Meats, Eggs, Nuts, Seeds & Legumes | DL14: 150 | DM14: 1 cup cooked green lentils (150g) | DV14: S | DW14: P | DX14: P | DY14: S | DZ14: NSW, SA, WA — cool-season dryland; planted May, harvested Sep–Nov | EA14: NH: Jun–Aug (Canada, Turkey, India) | EB14: Long Storage | EC14: Dry seed — cool/dry/dark, airtight | ED14: 12–36 months | EE14: 1 | EF14: 1–3 years
A15: Wheat (Whole) | B15: Grain | C15: Wheat, whole, uncooked | D15: 325.5 | E15: 11.2 | F15: 2.4 | G15: 58.3 | H15: 11.4 | I15: 35 | J15: 3.43 | K15: 120 | L15: 302 | M15: 315 | N15: 2 | O15: 2 | R15: 15.6 | S15: 0 | T15: 0.93 | U15: 0 | V15: 0.456 | W15: 0.1 | X15: 4.18 | Y15: 0.2 | Z15: 0 | AA15: 47 | AB15: 2114 | AC15: Triticum aestivum | AD15: L. | AE15: Liliopsida:Commelinidae:Cyperales:Gramineae | AF15: Triticum hybernum L., Sp. Pl. 86 (1753), Triticum sativum Lam., Fl. Franç. 3: 625 (1778), Triticum vulgare Vill., Hist. Pl. Dauphiné 2: 153 (1783), Triticum cereale Schrank, Baier. Fl. 1: 387 (1789) | AG15: wheat | AH15: wheat, bread wheat, blé, alkamh, sinde, xiao mai, trigo, brödvete, vanligt vete, kveite, almindelig hvede, leipävehnä, vehnä, hveiti, aat-weize, weizen, grano, frumento, lua mi, froment, cereals-wheat | AI15: suitable | AJ15: grass | AK15: erect | AL15: annual | AM15: COOL | AN15: single stem, C3 photosynthesis | AO15: cereals & pseudocereals, forage/pasture, medicinals & aromatic | AP15: cereals & pseudocereals | AQ15: grown on large scale | AR15: 15 | AS15: 23 | AT15: 5 | AU15: 27 | AV15: 750 | AW15: 900 | AX15: 300 | AY15: 1600 | AZ15: 6 | BA15: 7 | BB15: 5.5 | BC15: 8.5 | BD15: 30 | BF15: 60 | BG15: 65 | BH15: 4500 | BI15: very bright | BJ15: very bright | BK15: cloudy skies | BL15: very bright | BM15: medium (50-150 cm) | BN15: shallow (20-50 cm) | BO15: medium, organic | BP15: heavy, medium | BQ15: high | BR15: moderate | BU15: low (<4 dS/m) | BV15: medium (4-10 dS/m) | BW15: well (dry spells) | BX15: well (dry spells) | BY15: -20 | BZ15: 0 | CA15: neutral day (12-14 hours), long day (>14 hours) | CB15: tropical wet & dry (Aw), tropical wet (Ar), desert or arid (Bw), steppe or semiarid (Bs), subtropical humid (Cf), subtropical dry summer (Cs), subtropical dry winter (Cw), temperate oceanic (Do), temperate continental (Dc), temperate with humid winters (Df), temperate with dry winters (Dw) | CF15: large scale/commercial | CG15: 90 | CH15: 250 | CI15: 0.6 | CJ15: 1.2 | CK15: 0.1 | CL15: 0.2 | CM15: Annual grass | CN15: 1 | CO15: 10 | CP15: Low: subsistence/dryland; High: UK/Netherlands irrigated | CQ15: FAOSTAT QCL | CR15: 3 | CS15: 1 | CT15: 1 | CU15: 1 | CV15: 1 | CW15: 0 | CX15: 1 | CY15: 2 | CZ15: 1 | DA15: 120 | DB15: 40 | DC15: 80 | DD15: 20 | DE15: 15 | DF15: 0 | DG15: 10 | DH15: 250 | DI15: 40 | DJ15: ERS wheat 2019; FAO mechanisation; LIT (Ibarrola-Rivas 2016) | DK15: Grain (Cereal) Foods | DL15: 100 | DM15: ½ cup cooked whole wheat berries; or 40g wholemeal bread | DN15: S | DW15: S | DX15: P | DY15: P | DZ15: WA Wheatbelt, NSW, VIC, SA — winter wheat harvested Oct–Jan; QLD spring wheat Oct–Nov | EA15: NH: Jun–Aug (Europe, N America, India) | EB15: Long Storage | EC15: Dry grain — cool/dry/dark, airtight | ED15: 12–60 months | EE15: 1 | EF15: 1–5 years
A16: Sorghum | B16: Grain | C16: Sorghum, grain, uncooked | D16: 350.1 | E16: 8.2 | F16: 3.6 | G16: 65.8 | H16: 8.6 | I16: 10 | J16: 2.25 | K16: 124 | L16: 273 | M16: 363 | N16: 1 | O16: 1.35 | R16: 15.5 | S16: 0 | T16: 0.4 | U16: 0 | V16: 0.4 | W16: 0.025 | X16: 4.05 | Y16: 0.1 | Z16: 0 | AA16: 20 | CI16: 0.9 | CJ16: 3.5 | CK16: 0.2 | CL16: 0.5 | CM16: Annual grass; grain sorghum | CN16: 0.5 | CO16: 6 | CP16: Low: dryland Africa; High: irrigated USA/Australia | CQ16: FAOSTAT QCL | CR16: 4 | CS16: 1 | CT16: 2 | CU16: 1 | CV16: 1 | CW16: 0 | CX16: 1 | CY16: 3 | CZ16: 2 | DA16: 130 | DB16: 50 | DC16: 120 | DD16: 20 | DE16: 15 | DF16: 0 | DG16: 10 | DH16: 250 | DI16: 50 | DJ16: ERS; LIT (Sudan Gezira) | DK16: Grain (Cereal) Foods | DL16: 100 | DM16: ½ cup cooked sorghum (~100g) | DO16: S | DP16: P | DQ16: P | DR16: P | DS16: S | DZ16: QLD/northern NSW — warm-season grain; harvested autumn Feb–May | EA16: NH: Aug–Oct (USA Great Plains, Africa) | EB16: Long Storage | EC16: Dry grain — cool/dry/dark, airtight | ED16: 12–36 months | EE16: 1 | EF16: 1–3 years
A17: Pumpkin Seed | B17: Seed | C17: Seed, pumpkin, hulled & dried | D17: 537.5 | E17: 30.2 | F17: 45 | G17: 2.1 | H17: 4.6 | I17: 40 | J17: 8.5 | K17: 530 | L17: 1100 | M17: 700 | N17: 1 | O17: 6.5 | P17: 1.2 | Q17: 4.2 | R17: 15 | S17: 2 | T17: 4.58 | U17: 0 | V17: 0.17 | W17: 0.06 | X17: 3.3 | Y17: 0 | Z17: 0 | AA17: 34 | AB17: 819 | AC17: Cucurbita maxima | AD17: Duchesne | AE17: Magnoliopsida:Dilleniidae:Violales:Cucurbitaceae | AG17: pumpkin | AH17: pumpkin, squash, giant squash, citrouille, hina, wavukani, te baukin, panikeni, poosani, hubbard squash, Kürbis | AI17: suitable | AJ17: vine | AK17: climber/scrambler/scadent | AL17: annual | AM17: WARM | AO17: forage/pasture, fruits & nuts, vegetables, materials, medicinals & aromatic | AP17: forage/pasture | AQ17: grown on large scale | AR17: 20 | AS17: 30 | AT17: 9 | AU17: 38 | AV17: 600 | AW17: 1000 | AX17: 450 | AY17: 2700 | AZ17: 5.5 | BA17: 7.5 | BB17: 5 | BC17: 8.5 | BD17: 10 | BF17: 20 | BG17: 50 | BH17: 2000 | BI17: very bright | BJ17: very bright | BK17: very bright | BL17: cloudy skies | BM17: deep (>>150 cm) | BN17: shallow (20-50 cm) | BO17: heavy, medium, light, organic | BP17: heavy, medium, light | BQ17: high | BR17: low | BU17: low (<4 dS/m) | BV17: low (<4 dS/m) | BW17: well (dry spells) | BX17: well (dry spells) | CA17: short day (<12 hours), neutral day (12-14 hours), long day (>14 hours) | CB17: tropical wet & dry (Aw), tropical wet (Ar), steppe or semiarid (Bs), subtropical humid (Cf), subtropical dry summer (Cs), subtropical dry winter (Cw), temperate oceanic (Do), temperate continental (Dc), temperate with humid winters (Df), temperate with dry winters (Dw) | CF17: home garden, large scale/commercial | CG17: 80 | CH17: 140 | CI17: 0.3 | CJ17: 0.6 | CK17: 3 | CL17: 8 | CM17: Vine; same plant as pumpkin | CN17: 0.3 | CO17: 1.5 | CP17: Hull-less (Styrian) pumpkin seed; Austria/Slovenia | CQ17: Est. FAOSTAT | CR17: 4 | CS17: 3 | CT17: 4 | CU17: 2 | CV17: 2 | CW17: 0 | CX17: 3 | CY17: 10 | CZ17: 8 | DA17: 130 | DB17: 60 | DC17: 130 | DD17: 20 | DE17: 15 | DF17: 0 | DG17: 30 | DH17: 250 | DI17: 150 | DJ17: EXT Austria/Slovenia hull-less pumpkin seed; LIT | DK17: Lean Meats, Eggs, Nuts, Seeds & Legumes | DL17: 30 | DM17: 30g pumpkin seeds (~2 tbsp); occasional substitute | DO17: S | DP17: P | DQ17: P | DR17: P | DS17: S | DZ17: Warm-season; harvested with pumpkin crop; autumn Feb–Jun | EA17: NH: Sep–Nov (Austria, China) | EB17: Medium Storage | EC17: Dry seed — cool/dark, airtight | ED17: 3–12 months | EE17: 3 | EF17: 0.2–1 years
A18: Garlic | B18: Bulb/Clove | C18: Garlic, peeled, fresh, raw | D18: 124.8 | E18: 6.1 | F18: 2.8 | G18: 10.2 | H18: 16.9 | I18: 30 | J18: 1.7 | K18: 25 | L18: 32 | M18: 510 | N18: 8 | O18: 1 | R18: 14.2 | S18: 2 | T18: 0.08 | U18: 11 | V18: 0.09 | W18: 0.06 | X18: 0.8 | Y18: 1.24 | Z18: 0 | AA18: 3 | AB18: 367 | AC18: Allium sativum | AD18: L. | AE18: Liliopsida:Liliidae:Asparagales:Alliaceae | AF18: Porrum sativum Reh. | AG18: garlic | AH18: garlic, cultivated garlic, ail, aglio, ajo, kaliki, Knoblauch, vitlök, hvidløg, thum, knoflook, alho, alho de cultura, chesnok, ninniku, suan, Bulbus Allii Sativi, garlic oil | AI18: suitable | AJ18: herb | AK18: erect | AL18: biennial | AN18: single stem | AO18: vegetables, medicinals & aromatic | AP18: vegetables | AQ18: grown on large scale | AR18: 18 | AS18: 30 | AT18: 7 | AU18: 35 | AV18: 750 | AW18: 1600 | AX18: 500 | AY18: 2700 | AZ18: 6 | BA18: 6.6 | BB18: 5 | BC18: 8.5 | BF18: 60 | BG18: 60 | BH18: 2200 | BI18: clear skies | BJ18: clear skies | BK18: very bright | BL18: cloudy skies | BM18: medium (50-150 cm) | BN18: shallow (20-50 cm) | BO18: medium, light | BP18: heavy, medium, light | BQ18: high | BR18: low | BU18: low (<4 dS/m) | BV18: low (<4 dS/m) | BW18: well (dry spells) | BX18: well (dry spells) | BY18: -5 | BZ18: -5 | CA18: long day (>14 hours) | CB18: tropical wet & dry (Aw), tropical wet (Ar), subtropical humid (Cf), subtropical dry summer (Cs), subtropical dry winter (Cw), temperate oceanic (Do), temperate continental (Dc), temperate with humid winters (Df), temperate with dry winters (Dw) | CD18: humidity | CF18: home garden, large scale/commercial | CG18: 90 | CH18: 120 | CI18: 0.3 | CJ18: 0.8 | CK18: 0.1 | CL18: 0.2 | CM18: Annual; bulb vegetable | CN18: 5 | CO18: 20 | CP18: Bulb yield (fresh); China >15 t/ha; small farms lower | CQ18: FAOSTAT QCL | CR18: 5 | CS18: 8 | CT18: 10 | CU18: 3 | CV18: 4 | CW18: 0 | CX18: 4 | CY18: 12 | CZ18: 10 | DA18: 140 | DB18: 200 | DC18: 280 | DD18: 30 | DE18: 35 | DF18: 0 | DG18: 40 | DH18: 350 | DI18: 200 | DJ18: EXT California; NSWDPI; AHDB HDC | DK18: Vegetables & Legumes | DL18: 75 | DM18: 2–3 cloves (~10g); typically used as condiment | DN18: P | DO18: S | DW18: S | DX18: P | DY18: P | DZ18: Riverina NSW, SA, VIC — planted autumn, harvested Nov–Jan; new season Dec | EA18: NH: Jun–Aug (China, Spain, Argentina) | EB18: Long Storage | EC18: Dry and braid; cool/dry shelf | ED18: 3–12 months | EE18: 3 | EF18: 1–9 months
A19: Spelt | B19: Grain | C19: Spelt, uncooked | D19: 331.7 | E19: 11.7 | F19: 3 | G19: 59.2 | H19: 8.8 | I19: 21 | J19: 2.8 | K19: 122 | L19: 323 | M19: 330 | N19: 3 | O19: 1.9 | P19: 0.65 | Q19: 3.7 | R19: 14 | S19: 0 | T19: 0.71 | U19: 0 | V19: 0.42 | W19: 0.03 | X19: 7.3 | Y19: 0.2 | Z19: 0 | AA19: 75 | AB19: 10591 | AC19: Triticum spelta | AD19: L. | AE19: Liliopsida:Commelinidae:Cyperales:Gramineae | AG19: spelt wheat | AH19: spelt wheat, wheat - spelt, farro, dinkel, German wheat | AI19: poorly suited | AJ19: grass | AK19: erect | AL19: annual | AM19: COOL | AO19: cereals & pseudocereals, forage/pasture | AP19: cereals & pseudocereals | AQ19: grown on small scale | AR19: 10 | AS19: 17 | AT19: 4 | AU19: 24 | AV19: 700 | AW19: 1000 | AX19: 300 | AY19: 1600 | AZ19: 6.5 | BA19: 7.5 | BB19: 5 | BC19: 8.3 | BI19: very bright | BJ19: clear skies | BK19: very bright | BL19: cloudy skies | BM19: medium (50-150 cm) | BN19: shallow (20-50 cm) | BO19: light | BP19: medium, light | BQ19: moderate | BR19: moderate | BU19: low (<4 dS/m) | BV19: low (<4 dS/m) | BW19: well (dry spells) | BX19: well (dry spells), excessive (dry/moderately dry) | CA19: long day (>14 hours) | CB19: steppe or semiarid (Bs), temperate oceanic (Do), temperate continental (Dc), temperate with humid winters (Df), temperate with dry winters (Dw) | CG19: 120 | CH19: 180 | CI19: 0.9 | CJ19: 1.5 | CK19: 0.1 | CL19: 0.2 | CM19: Annual grass; hulled wheat | CN19: 2 | CO19: 6 | CP19: Lower than common wheat; Germany/Austria organic | CQ19: FAOSTAT QCL | CR19: 3 | CS19: 1 | CT19: 2 | CU19: 1 | CV19: 1 | CW19: 0 | CX19: 0 | CY19: 3 | CZ19: 2 | DA19: 120 | DB19: 40 | DC19: 90 | DD19: 15 | DE19: 10 | DF19: 0 | DG19: 0 | DH19: 220 | DI19: 40 | DJ19: EXT Germany; LIT — dehulling adds postharvest | DK19: Grain (Cereal) Foods | DL19: 100 | DM19: ½ cup cooked spelt berries (~100g) | DN19: S | DW19: S | DX19: P | DY19: P | DZ19: VIC/NSW cool-temperate — same as wheat harvest | EA19: NH: Jul–Aug (Germany, Austria) | EB19: Long Storage | EC19: Dry grain — cool/dry/dark, airtight | ED19: 12–36 months | EE19: 1 | EF19: 1–3 years
A20: Rice (Brown) | B20: Grain | C20: Rice, brown, uncooked | D20: 347 | E20: 7.6 | F20: 3.1 | G20: 69.1 | H20: 3.5 | I20: 7 | J20: 0.8 | K20: 119 | L20: 314 | M20: 230 | N20: 2 | O20: 1.7 | P20: 0.3 | Q20: 4.7 | R20: 14 | S20: 0 | T20: 1.31 | U20: 0 | V20: 0.37 | W20: 0.01 | X20: 5.8 | Y20: 0.2 | Z20: 0 | AA20: 37 | AB20: 1574 | AC20: Oryza sativa | AD20: L. | AE20: Liliopsida:Commelinidae:Cyperales:Gramineae | AG20: rice | AH20: rice, riso, riz, arroz, raisi, chawal, dhan, shali, rais, kumi, kome, ku, dao, tao, kao, cau, byeo, padi, paddy, vrihi, arishi, oruza, lúa, lúa gao, arishi Arruz, reis | AI20: poorly suited | AJ20: grass | AK20: erect | AL20: annual | AM20: WARM | AN20: multi stem, C3 photosynthesis | AO20: cereals & pseudocereals | AP20: cereals & pseudocereals | AQ20: grown on large scale | AR20: 20 | AS20: 30 | AT20: 10 | AU20: 36 | AV20: 1500 | AW20: 2000 | AX20: 1000 | AY20: 4000 | AZ20: 5.5 | BA20: 7 | BB20: 4.5 | BC20: 9 | BF20: 36 | BG20: 55 | BH20: 2500 | BI20: very bright | BJ20: very bright | BK20: cloudy skies | BL20: very bright | BM20: medium (50-150 cm) | BN20: shallow (20-50 cm) | BO20: wide | BP20: wide | BQ20: high | BR20: moderate | BU20: low (<4 dS/m) | BV20: low (<4 dS/m) | BW20: poorly (saturated >50% of year) | BX20: poorly (saturated >50% of year) | CA20: neutral day (12-14 hours) | CB20: tropical wet & dry (Aw), tropical wet (Ar), subtropical humid (Cf), subtropical dry summer (Cs), subtropical dry winter (Cw) | CF20: intermediate (animal drawn), large scale/commercial | CG20: 80 | CH20: 180 | CI20: 0.8 | CJ20: 1.8 | CK20: 0.1 | CL20: 0.3 | CM20: Annual grass | CN20: 1.5 | CO20: 10 | CP20: Paddy yield (same crop as white rice); unhusked | CQ20: FAOSTAT QCL | CR20: 8 | CS20: 5 | CT20: 5 | CU20: 2 | CV20: 2 | CW20: 0 | CX20: 5 | CY20: 8 | CZ20: 5 | DA20: 180 | DB20: 200 | DC20: 250 | DD20: 30 | DE20: 20 | DF20: 0 | DG20: 60 | DH20: 350 | DI20: 80 | DJ20: IRRI; same as white rice — milling step not included (farm gate) | DK20: Grain (Cereal) Foods | DL20: 100 | DM20: ½ cup cooked brown rice (~100g) | DO20: S | DP20: P | DQ20: P | DR20: S | DZ20: Murrumbidgee NSW — same as white rice (less processing) | EA20: NH: Sep–Nov | EB20: Medium Storage | EC20: Cool/dry/dark, airtight — refrigerate for longer | ED20: 6–12 months | EE20: 1 | EF20: 0.5–1 years
A21: Rice (White) | B21: Grain | C21: Rice, white, uncooked | D21: 339.9 | E21: 7 | F21: 0.9 | G21: 74 | H21: 0.8 | I21: 4 | J21: 0.2 | K21: 20 | L21: 90 | M21: 58 | N21: 1 | O21: 1.2 | P21: 0.2 | Q21: 1.6 | R21: 14 | S21: 0 | T21: 0 | U21: 0 | V21: 0.05 | W21: 0 | X21: 1.2 | Y21: 0.1 | Z21: 0 | AA21: 20 | AB21: 1574 | AC21: Oryza sativa | AD21: L. | AE21: Liliopsida:Commelinidae:Cyperales:Gramineae | AG21: rice | AH21: rice, riso, riz, arroz, raisi, chawal, dhan, shali, rais, kumi, kome, ku, dao, tao, kao, cau, byeo, padi, paddy, vrihi, arishi, oruza, lúa, lúa gao, arishi Arruz, reis | AI21: poorly suited | AJ21: grass | AK21: erect | AL21: annual | AM21: WARM | AN21: multi stem, C3 photosynthesis | AO21: cereals & pseudocereals | AP21: cereals & pseudocereals | AQ21: grown on large scale | AR21: 20 | AS21: 30 | AT21: 10 | AU21: 36 | AV21: 1500 | AW21: 2000 | AX21: 1000 | AY21: 4000 | AZ21: 5.5 | BA21: 7 | BB21: 4.5 | BC21: 9 | BF21: 36 | BG21: 55 | BH21: 2500 | BI21: very bright | BJ21: very bright | BK21: cloudy skies | BL21: very bright | BM21: medium (50-150 cm) | BN21: shallow (20-50 cm) | BO21: wide | BP21: wide | BQ21: high | BR21: moderate | BU21: low (<4 dS/m) | BV21: low (<4 dS/m) | BW21: poorly (saturated >50% of year) | BX21: poorly (saturated >50% of year) | CA21: neutral day (12-14 hours) | CB21: tropical wet & dry (Aw), tropical wet (Ar), subtropical humid (Cf), subtropical dry summer (Cs), subtropical dry winter (Cw) | CF21: intermediate (animal drawn), large scale/commercial | CG21: 80 | CH21: 180 | CI21: 0.8 | CJ21: 1.8 | CK21: 0.1 | CL21: 0.3 | CM21: Annual grass | CN21: 1.5 | CO21: 10 | CP21: Paddy; Low: traditional rainfed; High: irrigated Asia (6-9 t/ha) | CQ21: FAOSTAT QCL | CR21: 8 | CS21: 5 | CT21: 5 | CU21: 2 | CV21: 2 | CW21: 0 | CX21: 5 | CY21: 8 | CZ21: 5 | DA21: 180 | DB21: 200 | DC21: 250 | DD21: 30 | DE21: 20 | DF21: 0 | DG21: 60 | DH21: 350 | DI21: 80 | DJ21: IRRI; FAO; ERS rice 2021; Ibarrola-Rivas 2016 | DK21: Grain (Cereal) Foods | DL21: 100 | DM21: ½ cup cooked white rice (~100g) | DO21: S | DP21: P | DQ21: P | DR21: S | DZ21: Murrumbidgee Irrigation Area NSW — planted Nov, harvested Feb–May | EA21: NH: Sep–Nov (China, India, SE Asia) | EB21: Long Storage | EC21: Dry grain — cool/dry/dark, airtight | ED21: 24–60 months | EE21: 1 | EF21: 2–5 years
A22: Millet | B22: Grain | C22: Millet, uncooked | D22: 354.4 | E22: 10.2 | F22: 3.5 | G22: 67.4 | H22: 3.7 | I22: 8 | J22: 5.2 | K22: 104 | L22: 231 | M22: 195 | N22: 1 | O22: 2.7 | R22: 13 | S22: 0 | T22: 0 | U22: 0 | V22: 0.31 | W22: 0.03 | X22: 5.1 | Y22: 0.2 | Z22: 0 | AA22: 85 | AB22: 8418 | AC22: Pennisetum glaucum | AD22: (L.) R.Br. | AE22: Liliopsida:Commelinidae:Cyperales:Gramineae | AF22: Pennisetum americanum, Pennisetum spicatum, Pennisetum typhoideum Rich., Pennisetum typhodes (Burm.) Stapf & C.E. Hubb. | AG22: pearl millett | AH22: pearl millett, bulrush millett, negrito millet, millet perle, petit millet, cumbu, bajra, bajri, babala, spiked millet, cat-tail millet, cattail millet, pijo perla, panizo Bajra, mil a chandella, mil penicillaire, dukn | AI22: poorly suited | AJ22: grass | AK22: erect | AL22: annual | AM22: WARM | AO22: cereals & pseudocereals | AP22: cereals & pseudocereals | AQ22: grown on large scale | AR22: 25 | AS22: 35 | AT22: 12 | AU22: 40 | AV22: 400 | AW22: 900 | AX22: 200 | AY22: 1700 | AZ22: 5 | BA22: 6.5 | BB22: 4.5 | BC22: 8.3 | BD22: 18 | BE22: 14 | BF22: 28 | BG22: 32 | BH22: 1800 | BI22: very bright | BJ22: very bright | BK22: very bright | BL22: clear skies | BM22: deep (>>150 cm) | BN22: medium (50-150 cm) | BO22: medium, light | BP22: medium, light | BQ22: moderate | BR22: low | BU22: low (<4 dS/m) | BV22: medium (4-10 dS/m) | BW22: well (dry spells) | BX22: well (dry spells), excessive (dry/moderately dry) | BY22: 2 | BZ22: 0 | CA22: short day (<12 hours), neutral day (12-14 hours) | CB22: tropical wet & dry (Aw), tropical wet (Ar), desert or arid (Bw), steppe or semiarid (Bs), subtropical humid (Cf), subtropical dry summer (Cs), subtropical dry winter (Cw) | CF22: home garden, small scale (manual), intermediate (animal drawn), large scale/commercial | CG22: 60 | CH22: 120 | CI22: 0.9 | CJ22: 3 | CK22: 0.1 | CL22: 0.3 | CM22: Annual grass; pearl millet | CN22: 0.3 | CO22: 2.5 | CP22: Pearl millet; Low: Sahel subsistence; High: managed India | CQ22: FAOSTAT QCL | CR22: 3 | CS22: 2 | CT22: 5 | CU22: 1 | CV22: 1 | CW22: 0 | CX22: 1 | CY22: 5 | CZ22: 3 | DA22: 120 | DB22: 60 | DC22: 200 | DD22: 15 | DE22: 10 | DF22: 0 | DG22: 10 | DH22: 300 | DI22: 80 | DJ22: FAO Sahel; LIT; CGIAR | DK22: Grain (Cereal) Foods | DL22: 100 | DM22: ½ cup cooked millet (~100g) | DO22: S | DP22: P | DQ22: P | DR22: P | DS22: S | DZ22: QLD/northern NSW — warm-season; harvested autumn | EA22: NH: Sep–Nov (India, Africa) | EB22: Long Storage | EC22: Dry grain — cool/dry/dark, airtight | ED22: 12–36 months | EE22: 1 | EF22: 1–3 years
A23: Sorghum | B23: Grain | C23: Sorghum Grain | D23: 329 | E23: 10.62 | F23: 72.09 | G23: 6.7 | H23: 3.46 | I23: 13 | J23: 3.36 | K23: 165 | L23: 289 | M23: 363 | N23: 2 | O23: 1.67 | P23: 0.284 | Q23: 1.605 | R23: 12.2 | S23: 0 | T23: 0.5 | U23: 0 | V23: 0.332 | W23: 0.096 | X23: 3.688 | Y23: 0.443 | Z23: 0 | AA23: 20 | AB23: 0 | AC23: 0 | AD23: 0 | AE23: 0 | AF23: 0 | AG23: 0 | AH23: 0 | AI23: 0 | AJ23: 0 | AK23: 0 | AL23: 0 | AM23: 0 | AN23: 0 | AO23: 0 | AP23: 0 | AQ23: 0 | AR23: 0 | AS23: 0 | AT23: 0 | AU23: 0 | AV23: 0 | AW23: 0 | AX23: 0 | AY23: 0 | AZ23: 0 | BA23: 0 | BB23: 0 | BC23: 0 | BD23: 0 | BE23: 0 | BF23: 0 | BG23: 0 | BH23: 0 | BI23: 0 | BJ23: 0 | BK23: 0 | BL23: 0 | BM23: 0 | BN23: 0 | BO23: 0 | BP23: 0 | BQ23: 0 | BR23: 0 | BS23: 0 | BT23: 0 | BU23: 0 | BV23: 0 | BW23: 0 | BX23: 0 | BY23: 0 | BZ23: 0 | CA23: 0 | CB23: 0 | CC23: 0 | CD23: 0 | CE23: 0 | CF23: 0 | CG23: 0 | CH23: 0 | CI23: 0.9 | CJ23: 3.5 | CK23: 0.2 | CL23: 0.5 | CM23: Annual grass; grain sorghum | CN23: 0.5 | CO23: 6 | CP23: Low: dryland Africa; High: irrigated USA/Australia | CQ23: FAOSTAT QCL | CR23: 4 | CS23: 1 | CT23: 2 | CU23: 1 | CV23: 1 | CW23: 0 | CX23: 1 | CY23: 3 | CZ23: 2 | DA23: 130 | DB23: 50 | DC23: 120 | DD23: 20 | DE23: 15 | DF23: 0 | DG23: 10 | DH23: 250 | DI23: 50 | DJ23: ERS; LIT (Sudan Gezira) | DK23: Grain (Cereal) Foods | DL23: 100 | DM23: ½ cup cooked sorghum (~100g) | DO23: S | DP23: P | DQ23: P | DR23: P | DS23: S | DZ23: QLD/northern NSW — warm-season grain; harvested autumn Feb–May | EA23: NH: Aug–Oct (USA Great Plains, Africa) | EB23: Long Storage | EC23: Dry grain — cool/dry/dark, airtight | ED23: 12–36 months | EE23: 1 | EF23: 1–3 years
A24: Peanut | B24: Nut | C24: Nut, peanut, with skin, raw, unsalted | D24: 567.9 | E24: 24.7 | F24: 47.1 | G24: 8.9 | H24: 8.2 | I24: 54 | J24: 2.3 | K24: 160 | L24: 370 | M24: 540 | N24: 1 | O24: 3 | P24: 0.81 | Q24: 1.7 | R24: 12 | S24: 1 | T24: 9.5 | U24: 0 | V24: 0.79 | W24: 0.12 | X24: 15 | Y24: 0.65 | Z24: 0 | AA24: 240 | AB24: 2199 | AC24: Arachis hypogaea | AD24: L. | AE24: Magnoliopsida:Rosidae:Fabales:Leguminosae | AG24: groundnut | AH24: groundnut, peanut, monkeynut, arachide, cacahuètes, Erdnuss, goober, mani, mani largo, pindels, pistach, pistache, pinat, pinati, earthnut, Manila nut, Chinese nut, pindar, goober pea, spagnoletta, nilakkadalai, kadalai | AI24: poorly suited | AJ24: herb | AK24: prostrate/procumbent/semi-erect | AL24: annual | AM24: WARM | AO24: pulses (grain legumes), vegetables, materials, medicinals & aromatic | AP24: pulses (grain legumes) | AQ24: grown on large scale | AR24: 22 | AS24: 32 | AT24: 10 | AU24: 45 | AV24: 600 | AW24: 1500 | AX24: 400 | AY24: 4000 | AZ24: 5.5 | BA24: 6.5 | BB24: 4.5 | BC24: 8.5 | BF24: 40 | BG24: 45 | BH24: 1650 | BI24: very bright | BJ24: very bright | BK24: very bright | BL24: clear skies | BM24: medium (50-150 cm) | BN24: medium (50-150 cm) | BO24: medium | BP24: heavy, medium, light, organic | BQ24: high | BR24: moderate | BU24: low (<4 dS/m) | BV24: low (<4 dS/m) | BW24: well (dry spells) | BX24: well (dry spells) | CA24: short day (<12 hours), neutral day (12-14 hours), long day (>14 hours) | CB24: tropical wet & dry (Aw), steppe or semiarid (Bs), subtropical humid (Cf) | CD24: hail, wind | CF24: large scale/commercial | CG24: 90 | CH24: 150 | CI24: 0.3 | CJ24: 0.6 | CK24: 0.3 | CL24: 0.6 | CM24: Annual herb; groundnut | CN24: 0.5 | CO24: 5 | CP24: Pod yield; Low: Africa subsistence; High: US/China irrigated | CQ24: FAOSTAT QCL | CR24: 5 | CS24: 5 | CT24: 8 | CU24: 2 | CV24: 3 | CW24: 0 | CX24: 2 | CY24: 10 | CZ24: 8 | DA24: 150 | DB24: 120 | DC24: 280 | DD24: 20 | DE24: 25 | DF24: 0 | DG24: 20 | DH24: 400 | DI24: 150 | DJ24: LIT Sudan Gezira (65 h/ha sow, peanut highest); ERS | DK24: Lean Meats, Eggs, Nuts, Seeds & Legumes | DL24: 30 | DM24: 30g peanuts or 2 tbsp peanut butter; occasional substitute | DP24: S | DQ24: P | DR24: P | DS24: S | DZ24: SE QLD (Kingaroy/South Burnett) — planted Nov, harvested Mar–May | EA24: NH: Sep–Nov (China, India, USA) | EB24: Long Storage | EC24: Dry in shell — cool/dry/dark | ED24: 6–12 months | EE24: 3 | EF24: 0.2–1 years
A25: Chia Seed | B25: Seed | C25: Seed, chia, dried | D25: 436.2 | E25: 23.8 | F25: 29.8 | G25: 3.1 | H25: 33.2 | I25: 530 | J25: 13 | K25: 380 | L25: 830 | M25: 720 | N25: 0 | O25: 5.4 | P25: 1.7 | Q25: 4.3 | R25: 12 | S25: 0 | T25: 1.06 | U25: 0 | V25: 0.24 | W25: 0.04 | X25: 7.6 | Y25: 0.12 | Z25: 0 | AA25: 111 | CI25: 0.6 | CJ25: 1.8 | CK25: 0.3 | CL25: 0.6 | CM25: Annual herb | CN25: 0.3 | CO25: 1.5 | CP25: Low: traditional Andean; High: commercial Mexico/Bolivia | CQ25: FAO; Est. | CR25: 3 | CS25: 2 | CT25: 4 | CU25: 1 | CV25: 2 | CW25: 0 | CX25: 2 | CY25: 5 | CZ25: 5 | DA25: 110 | DB25: 50 | DC25: 150 | DD25: 15 | DE25: 15 | DF25: 0 | DG25: 20 | DH25: 200 | DI25: 80 | DJ25: EXT Mexico/Bolivia; LIT | DK25: Lean Meats, Eggs, Nuts, Seeds & Legumes | DL25: 30 | DM25: 30g chia seeds (~2 tbsp); occasional substitute | DP25: S | DQ25: P | DR25: P | DS25: S | DZ25: NT/Kimberley WA — tropical crop; planted wet season, harvested Apr–May | EA25: NH: Oct–Nov (Mexico, Bolivia) | EB25: Long Storage | EC25: Dry seed — cool/dark, airtight | ED25: 24–48 months | EE25: 1 | EF25: 2–4 years
A26: Macadamia | B26: Nut | C26: Nut, macadamia, raw, unsalted | D26: 737.6 | E26: 6.5 | F26: 76.7 | G26: 4.6 | H26: 7.9 | I26: 51 | J26: 1.7 | K26: 110 | L26: 200 | M26: 370 | N26: 1 | O26: 1.1 | P26: 0.39 | Q26: 4.1 | R26: 11 | S26: 0 | T26: 0 | U26: 0 | V26: 0.31 | W26: 0.07 | X26: 0.9 | Y26: 0.27 | Z26: 0 | AA26: 22 | AB26: 1382 | AC26: Macadamia integrifolia | AD26: Maiden & Betche | AE26: Magnoliopsida:Rosidae:Proteales:Proteaceae | AG26: macadamia nut | AH26: macadamia nut, noz de macadamia | AI26: poorly suited | AJ26: tree | AK26: erect | AL26: perennial | AN26: evergreen, single stem | AO26: fruits & nuts, materials, ornamentals/turf, forest/wood, environmental | AP26: nuts | AR26: 10 | AS26: 26 | AT26: 8 | AU26: 35 | AV26: 1000 | AW26: 3000 | AX26: 700 | AY26: 3500 | AZ26: 5 | BA26: 6 | BB26: 4.5 | BC26: 7 | BD26: 15 | BF26: 35 | BG26: 40 | BH26: 1600 | BI26: clear skies | BJ26: very bright | BK26: clear skies | BL26: very bright | BM26: medium (50-150 cm) | BN26: medium (50-150 cm) | BO26: medium, light, organic | BP26: medium, light, organic | BQ26: moderate | BR26: moderate | BU26: low (<4 dS/m) | BV26: low (<4 dS/m) | BW26: well (dry spells) | BX26: well (dry spells) | CG26: 365 | CH26: 365 | CI26: 5 | CJ26: 18 | CK26: 5 | CL26: 12 | CM26: Tree | CN26: 0.5 | CO26: 5 | CP26: Nut in shell; Australia/Hawaii/SA commercial | CQ26: FAOSTAT QCL; Aust. | CR26: 0 | CS26: 0 | CT26: 5 | CU26: 4 | CV26: 5 | CW26: 8 | CX26: 4 | CY26: 10 | CZ26: 5 | DA26: 0 | DB26: 0 | DC26: 40 | DD26: 25 | DE26: 35 | DF26: 60 | DG26: 30 | DH26: 250 | DI26: 100 | DJ26: NSWDPI; EXT Hawaii; Aust. Macadamia Soc. | DK26: Lean Meats, Eggs, Nuts, Seeds & Legumes | DL26: 30 | DM26: 30g macadamia nuts (~10–12 nuts); occasional substitute | DP26: S | DQ26: P | DR26: P | DS26: P | DT26: P | DU26: S | DZ26: Northern NSW, SE QLD — main harvest Apr–Aug; peak May–Jul | EA26: NH: Oct–Jan (Hawaii, South Africa) | EB26: Long Storage | EC26: In-shell: cool/dry; shelled: refrigerate or freeze | ED26: 6–24 months | EE26: 3 | EF26: 0.2–1 years
A27: Coconut | B27: Flesh | C27: Nuts Coconut Meat Raw | D27: 354 | E27: 3.33 | F27: 15.23 | G27: 9 | H27: 33.49 | I27: 14 | J27: 2.43 | K27: 32 | L27: 113 | M27: 356 | N27: 20 | O27: 1.1 | P27: 0.435 | Q27: 1.5 | R27: 10.1 | S27: 0 | T27: 0.24 | U27: 3.3 | V27: 0.066 | W27: 0.02 | X27: 0.54 | Y27: 0.054 | Z27: 0 | AA27: 26 | AB27: 744 | AC27: Cocos nucifera | AD27: Linnaeus | AE27: Liliopsida:Arecidae:Arecales:Palmae | AF27: 0 | AG27: coconut | AH27: coconut, cocotier, palma de coco, cocotero, côco, narial, thengai, kokospalme, ye, tree of life, tree of heaven, kalpaviriksha, tree of abundance, natures supermarket, kulau, coir fibre, (See "Notes" for hybrid names) | AI27: poorly suited | AJ27: tree | AK27: erect | AL27: perennial | AM27: 0 | AN27: evergreen, single stem | AO27: fruits & nuts, materials, forest/wood | AP27: nuts | AQ27: grown on large scale, harvested from wild | AR27: 22 | AS27: 34 | AT27: 14 | AU27: 38 | AV27: 1200 | AW27: 2400 | AX27: 650 | AY27: 4000 | AZ27: 5 | BA27: 8 | BB27: 4.3 | BC27: 8.7 | BD27: 0 | BE27: 0 | BF27: 10 | BG27: 26 | BH27: 1500 | BI27: very bright | BJ27: very bright | BK27: very bright | BL27: cloudy skies | BM27: deep (>>150 cm) | BN27: medium (50-150 cm) | BO27: medium, light | BP27: heavy, medium, light | BQ27: moderate | BR27: low | BS27: 0 | BT27: 0 | BU27: low (<4 dS/m) | BV27: medium (4-10 dS/m) | BW27: well (dry spells) | BX27: well (dry spells) | BY27: -1 | BZ27: 0 | CA27: short day (<12 hours), neutral day (12-14 hours), long day (>14 hours) | CB27: tropical wet & dry (Aw), tropical wet (Ar) | CC27: 0 | CD27: 0 | CE27: 0 | CF27: 0 | CG27: 270 | CH27: 365 | CI27: 20 | CJ27: 30 | CK27: 5 | CL27: 9 | CM27: Tall palm; frond spread | CN27: 3 | CO27: 15 | CP27: Yield in nut equivalent; Low: unmanaged; High: hybrid | CQ27: FAOSTAT QCL; FAO | CR27: 0 | CS27: 0 | CT27: 10 | CU27: 4 | CV27: 5 | CW27: 5 | CX27: 5 | CY27: 25 | CZ27: 10 | DA27: 0 | DB27: 0 | DC27: 80 | DD27: 25 | DE27: 35 | DF27: 40 | DG27: 35 | DH27: 400 | DI27: 150 | DJ27: FAO Pacific; LIT — climbing harvest intensive | DK27: Discretionary | DL27: 30 | DM27: 30g coconut flesh; high saturated fat — discretionary | DN27: S | DO27: S | DP27: P | DQ27: P | DR27: P | DS27: P | DT27: S | DU27: S | DZ27: FNQ tropical coast — year-round; coconut water peak Feb–May; dry nut peak Apr–Jul | EA27: NH tropical: year-round (Philippines, Indonesia) | EB27: Medium Storage | EC27: Dry nut; desiccated or oil | ED27: 1–6 months | EE27: 5 | EF27: 1–3 months
A28: Lupin | B28: Seed | C28: Lupin, whole, uncooked | D28: 282.5 | E28: 28.6 | F28: 6.5 | G28: 7.4 | H28: 41.5 | I28: 211 | J28: 3.9 | K28: 171 | L28: 302 | M28: 570 | N28: 50 | O28: 3.4 | R28: 8.2 | S28: 33 | T28: 2.33 | U28: 2 | V28: 0.56 | W28: 0.02 | X28: 2.2 | Y28: 0.1 | Z28: 0 | AA28: 350 | AB28: 7435 | AC28: Lupinus mutabilis | AD28: Sweet | AE28: Magnoliopsida:Rosidae:Fabales:Leguminosae | AF28: Lupinus tauris | AG28: Andean lupin | AH28: Andean lupin, South American lupin, sweet Bolivian lupine, pearl lupin, altramuz, chocho, lupino, raewi (Peru, Bolivia), tauri (Bolivia), chocho (Ecuador, Peru), chochito (Ecuador, Peru), cequela (Peru), chuchus (Bolivia), tarwi, tauri | AI28: suitable | AJ28: herb | AK28: erect | AL28: annual | AM28: COOL | AN28: single stem | AO28: pulses (grain legumes), forage/pasture, ornamentals/turf, medicinals & aromatic | AP28: pulses (grain legumes) | AQ28: grown on small scale | AR28: 18 | AS28: 24 | AT28: 6 | AU28: 30 | AV28: 500 | AW28: 1000 | AX28: 350 | AY28: 1700 | AZ28: 5 | BA28: 6.5 | BB28: 4.5 | BC28: 7 | BF28: 22 | BG28: 50 | BH28: 4000 | BI28: very bright | BJ28: clear skies | BK28: very bright | BL28: cloudy skies | BM28: shallow (20-50 cm) | BN28: shallow (20-50 cm) | BO28: medium, light | BP28: heavy, medium, light | BQ28: moderate | BR28: low | BU28: low (<4 dS/m) | BV28: medium (4-10 dS/m) | BW28: well (dry spells) | BX28: well (dry spells), excessive (dry/moderately dry) | BY28: -5 | BZ28: -5 | CA28: short day (<12 hours), neutral day (12-14 hours), long day (>14 hours) | CB28: tropical wet & dry (Aw), steppe or semiarid (Bs), subtropical humid (Cf), subtropical dry summer (Cs), subtropical dry winter (Cw), temperate oceanic (Do), temperate continental (Dc), temperate with humid winters (Df), temperate with dry winters (Dw) | CG28: 150 | CH28: 330 | CI28: 0.5 | CJ28: 1.5 | CK28: 0.3 | CL28: 0.6 | CM28: Annual herb | CN28: 0.5 | CO28: 3.5 | CP28: Dry seed; Australia dominant; white lupin higher potential | CQ28: FAOSTAT QCL | CR28: 3 | CS28: 2 | CT28: 3 | CU28: 1 | CV28: 2 | CW28: 0 | CX28: 1 | CY28: 4 | CZ28: 3 | DA28: 120 | DB28: 50 | DC28: 120 | DD28: 10 | DE28: 15 | DF28: 0 | DG28: 10 | DH28: 220 | DI28: 60 | DJ28: EXT Australia GRDC; LIT | DK28: Lean Meats, Eggs, Nuts, Seeds & Legumes | DL28: 150 | DM28: 1 cup cooked lupin beans (150g) | DV28: S | DW28: P | DX28: P | DY28: S | DZ28: WA (dominant producer), SA, VIC — cool-season; harvested Oct–Nov | EA28: NH: Jul–Aug (Poland, Australia exports) | EB28: Long Storage | EC28: Dry seed — cool/dry/dark | ED28: 12–24 months | EE28: 2 | EF28: 1–2 years
A29: Sunflower Seed | B29: Seed | C29: Seed, sunflower | D29: 564.5 | E29: 24.7 | F29: 48.3 | G29: 3.1 | H29: 13 | I29: 99 | J29: 4.85 | K29: 370 | L29: 775 | M29: 610 | N29: 0 | O29: 5.44 | P29: 2 | Q29: 2.1 | R29: 7.5 | S29: 0 | T29: 41.21 | U29: 0 | V29: 0.875 | W29: 0.16 | X29: 10.75 | Y29: 0.56 | Z29: 0 | AA29: 126 | CI29: 0.9 | CJ29: 3.5 | CK29: 0.3 | CL29: 0.9 | CM29: Annual herb; oilseed types | CN29: 0.5 | CO29: 4 | CP29: Oil seed type; Low: dryland; High: irrigated EU/Ukraine | CQ29: FAOSTAT QCL | CR29: 3 | CS29: 1 | CT29: 3 | CU29: 1 | CV29: 2 | CW29: 0 | CX29: 1 | CY29: 3 | CZ29: 2 | DA29: 120 | DB29: 45 | DC29: 100 | DD29: 15 | DE29: 15 | DF29: 0 | DG29: 10 | DH29: 200 | DI29: 40 | DJ29: ERS; NSWDPI; LIT | DK29: Lean Meats, Eggs, Nuts, Seeds & Legumes | DL29: 30 | DM29: 30g sunflower seeds (~3 tbsp); occasional substitute | DO29: S | DP29: P | DQ29: P | DR29: S | DZ29: QLD/NSW — warm-season oilseed; Feb–May harvest | EA29: NH: Sep–Oct (Ukraine, Russia, Argentina) | EB29: Medium Storage | EC29: Dry seed — cool/dark, airtight | ED29: 3–12 months | EE29: 2 | EF29: 0.2–1 years
A30: Oats (Rolled) | B30: Grain | C30: Oats, rolled, uncooked | D30: 373.8 | E30: 12.2 | F30: 9.5 | G30: 54.5 | H30: 9.5 | I30: 40 | J30: 3.5 | K30: 104 | L30: 310 | M30: 310 | N30: 2 | O30: 2.35 | R30: 6.5 | S30: 0 | T30: 0.23 | U30: 0 | V30: 0.39 | W30: 0.005 | X30: 1.25 | Y30: 0.2 | Z30: 0 | AA30: 17 | AB30: 481 | AC30: Avena sativa | AD30: L. | AE30: Liliopsida:Commelinidae:Cyperales:Gramineae | AG30: oat | AH30: oat, oats, hawer, hafer, avena, avoine, avoine farine, vanlig havre, havre, almindelig havre, peltokaura, kaura, akurhafrar, saat-hafer | AI30: suitable | AJ30: grass | AK30: erect | AL30: annual | AM30: COOL | AO30: cereals & pseudocereals, cover crop | AP30: cereals & pseudocereals | AQ30: grown on large scale | AR30: 16 | AS30: 20 | AT30: 5 | AU30: 30 | AV30: 600 | AW30: 1000 | AX30: 250 | AY30: 1500 | AZ30: 5 | BA30: 6 | BB30: 4.5 | BC30: 7.5 | BD30: 45 | BE30: 40 | BF30: 60 | BG30: 60 | BI30: very bright | BJ30: very bright | BK30: very bright | BL30: cloudy skies | BM30: medium (50-150 cm) | BN30: shallow (20-50 cm) | BO30: heavy, medium, light | BP30: heavy, medium, light | BQ30: high | BR30: moderate | BU30: low (<4 dS/m) | BV30: low (<4 dS/m) | BW30: well (dry spells) | BX30: well (dry spells) | BY30: -15 | BZ30: -1 | CA30: neutral day (12-14 hours), long day (>14 hours) | CB30: tropical wet & dry (Aw), tropical wet (Ar), desert or arid (Bw), steppe or semiarid (Bs), subtropical humid (Cf), subtropical dry summer (Cs), subtropical dry winter (Cw), temperate oceanic (Do), temperate continental (Dc), temperate with humid winters (Df), temperate with dry winters (Dw) | CG30: 110 | CH30: 270 | CI30: 0.6 | CJ30: 1.5 | CK30: 0.1 | CL30: 0.2 | CM30: Annual grass | CN30: 1.5 | CO30: 7 | CP30: Grain yield; EU/Australia commercial; UK avg ~5.5 t/ha | CQ30: FAOSTAT QCL; HDC | CR30: 3 | CS30: 1 | CT30: 1 | CU30: 1 | CV30: 1 | CW30: 0 | CX30: 0 | CY30: 2 | CZ30: 1 | DA30: 110 | DB30: 40 | DC30: 70 | DD30: 15 | DE30: 10 | DF30: 0 | DG30: 0 | DH30: 200 | DI30: 30 | DJ30: AHDB; EXT Iowa State | DK30: Grain (Cereal) Foods | DL30: 120 | DM30: ½ cup cooked porridge (~120g) | DN30: S | DW30: S | DX30: P | DY30: P | DZ30: SA, VIC, WA, NSW — spring harvest Oct–Dec | EA30: NH: Jul–Aug (Finland, Canada) | EB30: Long Storage | EC30: Dry grain — cool/dry/dark, airtight | ED30: 12–24 months | EE30: 1 | EF30: 1–2 years
